Workbook

Sheet Validierung_Teststufe_1
A1: Pflichtattribute VSA-DSS-Mini | D1: Version VSA Checker Analytics
E4: Teststufe 1
E5: Abgabe Werkkataster | G5: Fehlerkategorie
E6: (%) Minimalanforderung | G6: (Fehler/Warnung) | J6: Objekte Total | K6: Objekte Total PAA | L6: Objekte Total SAA | M6: Fehler gefunden | O6: Fehler gefunden | Q6: Fehler gefunden | S6: Resultat
M7: Total | O7: PAA Objekte mit Wert "NULL" | Q7: SAA Objekte mit Wert "NULL" | S7: Fehlerkategorie + Anteil
A8: Prüfregel | B8: Klasse | C8: Attribut | D8: Constraints Wertebereich PAA/SAA AWA/AfU | E8: PAA | F8: SAA | G8: PAA | H8: SAA | I8: Relevant für Teilprojekt | J8: [Anzahl] | K8: [Anzahl] | L8: [Anzahl] | M8: [Anzahl] | N8: [Anteil in %] | O8: [Anzahl] | P8: [Anteil in %] | Q8: [Anzahl] | R8: [Anteil in %]
A9: 10001a | B9: ALR | C9: Beseitigung_Ist | I9: ALR | J9: =IF(E9="","",raw_data!C1) | K9: =IF(E27="","",raw_data!F17) | M9: =IF(E9="","",raw_data!F1) | N9: =IF(E9="","",IFERROR(M9/J9,"-")) | O9: =IF(E27="","",raw_data!G17) | S9: =IF(E9="","",IF(OR(NOT(ISNUMBER(N9)),N9<=(1-E9)),"erfüllt",IF(G9="Fehler","mit Fehler",IF(G9="Warnung","mit Warnung",""))))
A10: 10001b | B10: ALR | C10: Beseitigung_Ist | D10: not unbekannt | I10: ALR | J10: =IF(E10="","",raw_data!C2) | M10: =IF(E10="","",raw_data!F2) | N10: =IF(E10="","",IFERROR(M10/J10,"-")) | S10: =IF(E10="","",IF(OR(NOT(ISNUMBER(N10)),N10<=(1-E10)),"erfüllt",IF(G10="Fehler","mit Fehler",IF(G10="Warnung","mit Warnung",""))))
A11: 10002 | B11: ALR | C11: Bezeichnung | I11: ALR | J11: =IF(E11="","",raw_data!C3) | M11: =IF(E11="","",raw_data!F3) | N11: =IF(E11="","",IFERROR(M11/J11,"-")) | S11: =IF(E11="","",IF(OR(NOT(ISNUMBER(N11)),N11<=(1-E11)),"erfüllt",IF(G11="Fehler","mit Fehler",IF(G11="Warnung","mit Warnung",""))))
A12: 10003 | B12: ALR | C12: Datenherrref | I12: ALR | J12: =IF(E12="","",raw_data!C4) | M12: =IF(E12="","",raw_data!F4) | N12: =IF(E12="","",IFERROR(M12/J12,"-")) | S12: =IF(E12="","",IF(OR(NOT(ISNUMBER(N12)),N12<=(1-E12)),"erfüllt",IF(G12="Fehler","mit Fehler",IF(G12="Warnung","mit Warnung",""))))
A13: 10004 | B13: ALR | C13: Datenlieferantref | I13: ALR | J13: =IF(E13="","",raw_data!C5) | M13: =IF(E13="","",raw_data!F5) | N13: =IF(E13="","",IFERROR(M13/J13,"-")) | S13: =IF(E13="","",IF(OR(NOT(ISNUMBER(N13)),N13<=(1-E13)),"erfüllt",IF(G13="Fehler","mit Fehler",IF(G13="Warnung","mit Warnung",""))))
A14: 10005 | B14: ALR | C14: Einwohnerwerte | I14: ALR | J14: =IF(E14="","",raw_data!C6) | M14: =IF(E14="","",raw_data!F6) | N14: =IF(E14="","",IFERROR(M14/J14,"-")) | S14: =IF(E14="","",IF(OR(NOT(ISNUMBER(N14)),N14<=(1-E14)),"erfüllt",IF(G14="Fehler","mit Fehler",IF(G14="Warnung","mit Warnung",""))))
A15: 10006 | B15: ALR | C15: Lage | I15: ALR | J15: =IF(E15="","",raw_data!C7) | M15: =IF(E15="","",raw_data!F7) | N15: =IF(E15="","",IFERROR(M15/J15,"-")) | S15: =IF(E15="","",IF(OR(NOT(ISNUMBER(N15)),N15<=(1-E15)),"erfüllt",IF(G15="Fehler","mit Fehler",IF(G15="Warnung","mit Warnung",""))))
A16: 10007 | B16: ALR | C16: Letzte_Aenderung | I16: ALR | J16: =IF(E16="","",raw_data!C8) | M16: =IF(E16="","",raw_data!F8) | N16: =IF(E16="","",IFERROR(M16/J16,"-")) | S16: =IF(E16="","",IF(OR(NOT(ISNUMBER(N16)),N16<=(1-E16)),"erfüllt",IF(G16="Fehler","mit Fehler",IF(G16="Warnung","mit Warnung",""))))
A17: 10008 | B17: ALR | C17: Massnahmeref | I17: ALR | J17: =IF(E17="","",raw_data!C9) | M17: =IF(E17="","",raw_data!F9) | N17: =IF(E17="","",IFERROR(M17/J17,"-")) | S17: =IF(E17="","",IF(OR(NOT(ISNUMBER(N17)),N17<=(1-E17)),"erfüllt",IF(G17="Fehler","mit Fehler",IF(G17="Warnung","mit Warnung",""))))
A18: 10009 | B18: ALR | C18: Obj_Id_Entsorgung | I18: ALR | J18: =IF(E18="","",raw_data!C10) | M18: =IF(E18="","",raw_data!F10) | N18: =IF(E18="","",IFERROR(M18/J18,"-")) | S18: =IF(E18="","",IF(OR(NOT(ISNUMBER(N18)),N18<=(1-E18)),"erfüllt",IF(G18="Fehler","mit Fehler",IF(G18="Warnung","mit Warnung",""))))
A19: 10010 | B19: ALR | C19: Obj_Id_Entsorgung_Abwasserbauwerk | I19: ALR | J19: =IF(E19="","",raw_data!C11) | M19: =IF(E19="","",raw_data!F11) | N19: =IF(E19="","",IFERROR(M19/J19,"-")) | S19: =IF(E19="","",IF(OR(NOT(ISNUMBER(N19)),N19<=(1-E19)),"erfüllt",IF(G19="Fehler","mit Fehler",IF(G19="Warnung","mit Warnung",""))))
A20: 10011 | B20: ALR | C20: Obj_Id_Entsorgung_Einleitstelle | I20: ALR | J20: =IF(E20="","",raw_data!C12) | M20: =IF(E20="","",raw_data!F12) | N20: =IF(E20="","",IFERROR(M20/J20,"-")) | S20: =IF(E20="","",IF(OR(NOT(ISNUMBER(N20)),N20<=(1-E20)),"erfüllt",IF(G20="Fehler","mit Fehler",IF(G20="Warnung","mit Warnung",""))))
A21: 10012 | B21: ALR | C21: Obj_Id_Entsorgung_Versickerungsanlage | I21: ALR | J21: =IF(E21="","",raw_data!C13) | M21: =IF(E21="","",raw_data!F13) | N21: =IF(E21="","",IFERROR(M21/J21,"-")) | S21: =IF(E21="","",IF(OR(NOT(ISNUMBER(N21)),N21<=(1-E21)),"erfüllt",IF(G21="Fehler","mit Fehler",IF(G21="Warnung","mit Warnung",""))))
A22: 10013 | B22: ALR | C22: Obj_Id_Gebaeudegruppe_Entsorgung | I22: ALR | J22: =IF(E22="","",raw_data!C14) | M22: =IF(E22="","",raw_data!F14) | N22: =IF(E22="","",IFERROR(M22/J22,"-")) | S22: =IF(E22="","",IF(OR(NOT(ISNUMBER(N22)),N22<=(1-E22)),"erfüllt",IF(G22="Fehler","mit Fehler",IF(G22="Warnung","mit Warnung",""))))
A23: 10014 | B23: ALR | C23: OID | I23: ALR | J23: =IF(E23="","",raw_data!C15) | M23: =IF(E23="","",raw_data!F15) | N23: =IF(E23="","",IFERROR(M23/J23,"-")) | S23: =IF(E23="","",IF(OR(NOT(ISNUMBER(N23)),N23<=(1-E23)),"erfüllt",IF(G23="Fehler","mit Fehler",IF(G23="Warnung","mit Warnung",""))))
A24: 10015a | B24: ALR | C24: Sanierungsbedarf | I24: ALR | J24: =IF(E24="","",raw_data!C16) | M24: =IF(E24="","",raw_data!F16) | N24: =IF(E24="","",IFERROR(M24/J24,"-")) | S24: =IF(E24="","",IF(OR(NOT(ISNUMBER(N24)),N24<=(1-E24)),"erfüllt",IF(G24="Fehler","mit Fehler",IF(G24="Warnung","mit Warnung",""))))
A25: 10015b | B25: ALR | C25: Sanierungsbedarf | D25: not unbekannt | I25: ALR | J25: =IF(E25="","",raw_data!C17) | M25: =IF(E25="","",raw_data!F17) | N25: =IF(E25="","",IFERROR(M25/J25,"-")) | S25: =IF(E25="","",IF(OR(NOT(ISNUMBER(N25)),N25<=(1-E25)),"erfüllt",IF(G25="Fehler","mit Fehler",IF(G25="Warnung","mit Warnung",""))))
A26: 10016 | B26: ALR | C26: Sanierungsdatum | I26: ALR | J26: =IF(E26="","",raw_data!C18) | M26: =IF(E26="","",raw_data!F18) | N26: =IF(E26="","",IFERROR(M26/J26,"-")) | S26: =IF(E26="","",IF(OR(NOT(ISNUMBER(N26)),N26<=(1-E26)),"erfüllt",IF(G26="Fehler","mit Fehler",IF(G26="Warnung","mit Warnung",""))))
A27: 10017 | B27: ALR | C27: Sanierungskonzept | I27: ALR | J27: =IF(E27="","",raw_data!C19) | M27: =IF(E27="","",raw_data!F19) | N27: =IF(E27="","",IFERROR(M27/J27,"-")) | S27: =IF(E27="","",IF(OR(NOT(ISNUMBER(N27)),N27<=(1-E27)),"erfüllt",IF(G27="Fehler","mit Fehler",IF(G27="Warnung","mit Warnung",""))))
A28: 11001 | B28: Knoten | C28: Ara_Nr | I28: Anlagenkataster | J28: =IF(E28="","",raw_data!C20) | K28: =IF(E28="","",raw_data!D20) | L28: =IF(F28="","",raw_data!E20) | M28: =IF(E28="","",raw_data!F20) | N28: =IF(E28="","",IFERROR(M28/J28,"-")) | O28: =IF(E28="","",raw_data!G20) | P28: =IF(E28="","",IFERROR(O28/K28,"-")) | Q28: =IF(F28="","",raw_data!H20) | R28: =IF(F28="","",IFERROR(Q28/L28,"-")) | S28: =IF(E28="","",IF(OR(NOT(ISNUMBER(N28)),N28<=(1-E28)),"erfüllt",IF(G28="Fehler","mit Fehler",IF(G28="Warnung","mit Warnung",""))))
A29: 11002a | B29: Knoten | C29: Status | E29: 0.9 | F29: 0.9 | G29: Fehler | H29: Fehler | I29: Anlagenkataster | J29: =IF(E29="","",raw_data!C21) -> 0 | K29: =IF(E29="","",raw_data!D21) -> 0 | L29: =IF(F29="","",raw_data!E21) -> 0 | M29: =IF(E29="","",raw_data!F21) -> 0 | N29: =IF(E29="","",IFERROR(M29/J29,"-")) -> - | O29: =IF(E29="","",raw_data!G21) -> 0 | P29: =IF(E29="","",IFERROR(O29/K29,"-")) -> - | Q29: =IF(F29="","",raw_data!H21) -> 0 | R29: =IF(F29="","",IFERROR(Q29/L29,"-")) -> - | S29: =IF(E29="","",IF(OR(NOT(ISNUMBER(N29)),N29<=(1-E29)),"erfüllt",IF(G29="Fehler","mit Fehler",IF(G29="Warnung","mit Warnung","")))) -> erfüllt
A30: 11002b | B30: Knoten | C30: Status | D30: not unbekannt | I30: Anlagenkataster | J30: =IF(E30="","",raw_data!C22) | K30: =IF(E30="","",raw_data!D22) | L30: =IF(F30="","",raw_data!E22) | M30: =IF(E30="","",raw_data!F22) | N30: =IF(E30="","",IFERROR(M30/J30,"-")) | O30: =IF(E30="","",raw_data!G22) | P30: =IF(E30="","",IFERROR(O30/K30,"-")) | Q30: =IF(F30="","",raw_data!H22) | R30: =IF(F30="","",IFERROR(Q30/L30,"-")) | S30: =IF(E30="","",IF(OR(NOT(ISNUMBER(N30)),N30<=(1-E30)),"erfüllt",IF(G30="Fehler","mit Fehler",IF(G30="Warnung","mit Warnung",""))))
A31: 11003 | B31: Knoten | C31: Baujahr | I31: Anlagenkataster | J31: =IF(E31="","",raw_data!C23) | K31: =IF(E31="","",raw_data!D23) | L31: =IF(F31="","",raw_data!E23) | M31: =IF(E31="","",raw_data!F23) | N31: =IF(E31="","",IFERROR(M31/J31,"-")) | O31: =IF(E31="","",raw_data!G23) | P31: =IF(E31="","",IFERROR(O31/K31,"-")) | Q31: =IF(F31="","",raw_data!H23) | R31: =IF(F31="","",IFERROR(Q31/L31,"-")) | S31: =IF(E31="","",IF(OR(NOT(ISNUMBER(N31)),N31<=(1-E31)),"erfüllt",IF(G31="Fehler","mit Fehler",IF(G31="Warnung","mit Warnung",""))))
A32: 11004a | B32: Knoten | C32: Baulicherzustand | I32: Z-S-U | J32: =IF(E32="","",raw_data!C24) | K32: =IF(E32="","",raw_data!D24) | L32: =IF(F32="","",raw_data!E24) | M32: =IF(E32="","",raw_data!F24) | N32: =IF(E32="","",IFERROR(M32/J32,"-")) | O32: =IF(E32="","",raw_data!G24) | P32: =IF(E32="","",IFERROR(O32/K32,"-")) | Q32: =IF(F32="","",raw_data!H24) | R32: =IF(F32="","",IFERROR(Q32/L32,"-")) | S32: =IF(E32="","",IF(OR(NOT(ISNUMBER(N32)),N32<=(1-E32)),"erfüllt",IF(G32="Fehler","mit Fehler",IF(G32="Warnung","mit Warnung",""))))
A33: 11004b | B33: Knoten | C33: Baulicherzustand | D33: not unbekannt | I33: Z-S-U | J33: =IF(E33="","",raw_data!C25) | K33: =IF(E33="","",raw_data!D25) | L33: =IF(F33="","",raw_data!E25) | M33: =IF(E33="","",raw_data!F25) | N33: =IF(E33="","",IFERROR(M33/J33,"-")) | O33: =IF(E33="","",raw_data!G25) | P33: =IF(E33="","",IFERROR(O33/K33,"-")) | Q33: =IF(F33="","",raw_data!H25) | R33: =IF(F33="","",IFERROR(Q33/L33,"-")) | S33: =IF(E33="","",IF(OR(NOT(ISNUMBER(N33)),N33<=(1-E33)),"erfüllt",IF(G33="Fehler","mit Fehler",IF(G33="Warnung","mit Warnung",""))))
A34: 11005 | B34: Knoten | C34: Bemerkung | I34: Anlagenkataster | J34: =IF(E34="","",raw_data!C26) | K34: =IF(E34="","",raw_data!D26) | L34: =IF(F34="","",raw_data!E26) | M34: =IF(E34="","",raw_data!F26) | N34: =IF(E34="","",IFERROR(M34/J34,"-")) | O34: =IF(E34="","",raw_data!G26) | P34: =IF(E34="","",IFERROR(O34/K34,"-")) | Q34: =IF(F34="","",raw_data!H26) | R34: =IF(F34="","",IFERROR(Q34/L34,"-")) | S34: =IF(E34="","",IF(OR(NOT(ISNUMBER(N34)),N34<=(1-E34)),"erfüllt",IF(G34="Fehler","mit Fehler",IF(G34="Warnung","mit Warnung",""))))
A35: 11006 | B35: Knoten | C35: Betreiberref | I35: Anlagenkataster | J35: =IF(E35="","",raw_data!C27) | K35: =IF(E35="","",raw_data!D27) | L35: =IF(F35="","",raw_data!E27) | M35: =IF(E35="","",raw_data!F27) | N35: =IF(E35="","",IFERROR(M35/J35,"-")) | O35: =IF(E35="","",raw_data!G27) | P35: =IF(E35="","",IFERROR(O35/K35,"-")) | Q35: =IF(F35="","",raw_data!H27) | R35: =IF(F35="","",IFERROR(Q35/L35,"-")) | S35: =IF(E35="","",IF(OR(NOT(ISNUMBER(N35)),N35<=(1-E35)),"erfüllt",IF(G35="Fehler","mit Fehler",IF(G35="Warnung","mit Warnung",""))))
A36: 11007a | B36: Knoten | C36: Bezeichnung | I36: Anlagenkataster | J36: =IF(E36="","",raw_data!C28) | K36: =IF(E36="","",raw_data!D28) | L36: =IF(F36="","",raw_data!E28) | M36: =IF(E36="","",raw_data!F28) | N36: =IF(E36="","",IFERROR(M36/J36,"-")) | O36: =IF(E36="","",raw_data!G28) | P36: =IF(E36="","",IFERROR(O36/K36,"-")) | Q36: =IF(F36="","",raw_data!H28) | R36: =IF(F36="","",IFERROR(Q36/L36,"-")) | S36: =IF(E36="","",IF(OR(NOT(ISNUMBER(N36)),N36<=(1-E36)),"erfüllt",IF(G36="Fehler","mit Fehler",IF(G36="Warnung","mit Warnung",""))))
A37: 11007b | B37: Knoten | C37: Bezeichnung | D37: eindeutig | E37: 1 | F37: 1 | G37: Fehler | H37: Fehler | I37: Anlagenkataster | J37: =IF(E37="","",raw_data!C29) -> 0 | K37: =IF(E37="","",raw_data!D29) -> 0 | L37: =IF(F37="","",raw_data!E29) -> 0 | M37: =IF(E37="","",raw_data!F29) -> 0 | N37: =IF(E37="","",IFERROR(M37/J37,"-")) -> - | O37: =IF(E37="","",raw_data!G29) -> 0 | P37: =IF(E37="","",IFERROR(O37/K37,"-")) -> - | Q37: =IF(F37="","",raw_data!H29) -> 0 | R37: =IF(F37="","",IFERROR(Q37/L37,"-")) -> - | S37: =IF(E37="","",IF(OR(NOT(ISNUMBER(N37)),N37<=(1-E37)),"erfüllt",IF(G37="Fehler","mit Fehler",IF(G37="Warnung","mit Warnung","")))) -> erfüllt
A38: 11008 | B38: Knoten | C38: Datenherrref | I38: Anlagenkataster | J38: =IF(E38="","",raw_data!C30) | K38: =IF(E38="","",raw_data!D30) | L38: =IF(F38="","",raw_data!E30) | M38: =IF(E38="","",raw_data!F30) | N38: =IF(E38="","",IFERROR(M38/J38,"-")) | O38: =IF(E38="","",raw_data!G30) | P38: =IF(E38="","",IFERROR(O38/K38,"-")) | Q38: =IF(F38="","",raw_data!H30) | R38: =IF(F38="","",IFERROR(Q38/L38,"-")) | S38: =IF(E38="","",IF(OR(NOT(ISNUMBER(N38)),N38<=(1-E38)),"erfüllt",IF(G38="Fehler","mit Fehler",IF(G38="Warnung","mit Warnung",""))))
A39: 11009 | B39: Knoten | C39: Datenlieferantref | I39: Anlagenkataster | J39: =IF(E39="","",raw_data!C31) | K39: =IF(E39="","",raw_data!D31) | L39: =IF(F39="","",raw_data!E31) | M39: =IF(E39="","",raw_data!F31) | N39: =IF(E39="","",IFERROR(M39/J39,"-")) | O39: =IF(E39="","",raw_data!G31) | P39: =IF(E39="","",IFERROR(O39/K39,"-")) | Q39: =IF(F39="","",raw_data!H31) | R39: =IF(F39="","",IFERROR(Q39/L39,"-")) | S39: =IF(E39="","",IF(OR(NOT(ISNUMBER(N39)),N39<=(1-E39)),"erfüllt",IF(G39="Fehler","mit Fehler",IF(G39="Warnung","mit Warnung",""))))
A40: 11010 | B40: Knoten | C40: Deckelkote | I40: Entwässerungskonzept | J40: =IF(E40="","",raw_data!C32) | K40: =IF(E40="","",raw_data!D32) | L40: =IF(F40="","",raw_data!E32) | M40: =IF(E40="","",raw_data!F32) | N40: =IF(E40="","",IFERROR(M40/J40,"-")) | O40: =IF(E40="","",raw_data!G32) | P40: =IF(E40="","",IFERROR(O40/K40,"-")) | Q40: =IF(F40="","",raw_data!H32) | R40: =IF(F40="","",IFERROR(Q40/L40,"-")) | S40: =IF(E40="","",IF(OR(NOT(ISNUMBER(N40)),N40<=(1-E40)),"erfüllt",IF(G40="Fehler","mit Fehler",IF(G40="Warnung","mit Warnung",""))))
A41: 11011 | B41: Knoten | C41: Detailgeometrie | I41: Anlagenkataster | J41: =IF(E41="","",raw_data!C33) | K41: =IF(E41="","",raw_data!D33) | L41: =IF(F41="","",raw_data!E33) | M41: =IF(E41="","",raw_data!F33) | N41: =IF(E41="","",IFERROR(M41/J41,"-")) | O41: =IF(E41="","",raw_data!G33) | P41: =IF(E41="","",IFERROR(O41/K41,"-")) | Q41: =IF(F41="","",raw_data!H33) | R41: =IF(F41="","",IFERROR(Q41/L41,"-")) | S41: =IF(E41="","",IF(OR(NOT(ISNUMBER(N41)),N41<=(1-E41)),"erfüllt",IF(G41="Fehler","mit Fehler",IF(G41="Warnung","mit Warnung",""))))
A42: 11012 | B42: Knoten | C42: Dimension1 | I42: Anlagenkataster | J42: =IF(E42="","",raw_data!C34) | K42: =IF(E42="","",raw_data!D34) | L42: =IF(F42="","",raw_data!E34) | M42: =IF(E42="","",raw_data!F34) | N42: =IF(E42="","",IFERROR(M42/J42,"-")) | O42: =IF(E42="","",raw_data!G34) | P42: =IF(E42="","",IFERROR(O42/K42,"-")) | Q42: =IF(F42="","",raw_data!H34) | R42: =IF(F42="","",IFERROR(Q42/L42,"-")) | S42: =IF(E42="","",IF(OR(NOT(ISNUMBER(N42)),N42<=(1-E42)),"erfüllt",IF(G42="Fehler","mit Fehler",IF(G42="Warnung","mit Warnung",""))))
...

Sheet Validierung_Teststufe_2
A1: Pflichtattribute VSA-DSS-Mini | D1: Version VSA Checker Analytics
E4: Teststufe 2
E5: Abgabe GEP | G5: Fehlerkategorie
E6: (%) Minimalanforderung | G6: (Fehler/Warnung) | J6: Objekte Total | K6: Objekte Total PAA | L6: Objekte Total SAA | M6: Fehler gefunden | O6: Fehler gefunden | Q6: Fehler gefunden | S6: Resultat
M7: Total | O7: PAA Objekte mit Wert "NULL" | Q7: SAA Objekte mit Wert "NULL" | S7: Fehlerkategorie + Anteil
A8: Prüfregel | B8: Klasse | C8: Attribut | D8: Constraints Wertebereich PAA/SAA AWA/AfU | E8: PAA | F8: SAA | G8: PAA | H8: SAA | I8: Relevant für Teilprojekt | J8: [Anzahl] | K8: [Anzahl] | L8: [Anzahl] | M8: [Anzahl] | N8: [Anteil in %] | O8: [Anzahl] | P8: [Anteil in %] | Q8: [Anzahl] | R8: [Anteil in %]
A9: 10001a | B9: ALR | C9: Beseitigung_Ist | E9: 0.95 | G9: Warnung | I9: ALR | J9: =IF(E9="","",raw_data!C1) -> 0 | K9: =IF(E27="","",raw_data!F17) | M9: =IF(E9="","",raw_data!F1) -> 0 | N9: =IF(E9="","",IFERROR(M9/J9,"-")) -> - | O9: =IF(E27="","",raw_data!G17) | S9: =IF(E9="","",IF(OR(NOT(ISNUMBER(N9)),N9<=(1-E9)),"erfüllt",IF(G9="Fehler","mit Fehler",IF(G9="Warnung","mit Warnung","")))) -> erfüllt
A10: 10001b | B10: ALR | C10: Beseitigung_Ist | D10: not unbekannt | E10: 0.5 | G10: Warnung | I10: ALR | J10: =IF(E10="","",raw_data!C2) -> 0 | M10: =IF(E10="","",raw_data!F2) -> 0 | N10: =IF(E10="","",IFERROR(M10/J10,"-")) -> - | S10: =IF(E10="","",IF(OR(NOT(ISNUMBER(N10)),N10<=(1-E10)),"erfüllt",IF(G10="Fehler","mit Fehler",IF(G10="Warnung","mit Warnung","")))) -> erfüllt
A11: 10002 | B11: ALR | C11: Bezeichnung | E11: 1 | G11: Fehler | I11: ALR | J11: =IF(E11="","",raw_data!C3) -> 0 | M11: =IF(E11="","",raw_data!F3) -> 0 | N11: =IF(E11="","",IFERROR(M11/J11,"-")) -> - | S11: =IF(E11="","",IF(OR(NOT(ISNUMBER(N11)),N11<=(1-E11)),"erfüllt",IF(G11="Fehler","mit Fehler",IF(G11="Warnung","mit Warnung","")))) -> erfüllt
A12: 10003 | B12: ALR | C12: Datenherrref | E12: 1 | G12: Warnung | I12: ALR | J12: =IF(E12="","",raw_data!C4) -> 0 | M12: =IF(E12="","",raw_data!F4) -> 0 | N12: =IF(E12="","",IFERROR(M12/J12,"-")) -> - | S12: =IF(E12="","",IF(OR(NOT(ISNUMBER(N12)),N12<=(1-E12)),"erfüllt",IF(G12="Fehler","mit Fehler",IF(G12="Warnung","mit Warnung","")))) -> erfüllt
A13: 10004 | B13: ALR | C13: Datenlieferantref | E13: 1 | G13: Fehler | I13: ALR | J13: =IF(E13="","",raw_data!C5) -> 0 | M13: =IF(E13="","",raw_data!F5) -> 0 | N13: =IF(E13="","",IFERROR(M13/J13,"-")) -> - | S13: =IF(E13="","",IF(OR(NOT(ISNUMBER(N13)),N13<=(1-E13)),"erfüllt",IF(G13="Fehler","mit Fehler",IF(G13="Warnung","mit Warnung","")))) -> erfüllt
A14: 10005 | B14: ALR | C14: Einwohnerwerte | E14: 1 | G14: Warnung | I14: ALR | J14: =IF(E14="","",raw_data!C6) -> 0 | M14: =IF(E14="","",raw_data!F6) -> 0 | N14: =IF(E14="","",IFERROR(M14/J14,"-")) -> - | S14: =IF(E14="","",IF(OR(NOT(ISNUMBER(N14)),N14<=(1-E14)),"erfüllt",IF(G14="Fehler","mit Fehler",IF(G14="Warnung","mit Warnung","")))) -> erfüllt
A15: 10006 | B15: ALR | C15: Lage | E15: 1 | G15: Fehler | I15: ALR | J15: =IF(E15="","",raw_data!C7) -> 0 | M15: =IF(E15="","",raw_data!F7) -> 0 | N15: =IF(E15="","",IFERROR(M15/J15,"-")) -> - | S15: =IF(E15="","",IF(OR(NOT(ISNUMBER(N15)),N15<=(1-E15)),"erfüllt",IF(G15="Fehler","mit Fehler",IF(G15="Warnung","mit Warnung","")))) -> erfüllt
A16: 10007 | B16: ALR | C16: Letzte_Aenderung | I16: ALR | J16: =IF(E16="","",raw_data!C8) | M16: =IF(E16="","",raw_data!F8) | N16: =IF(E16="","",IFERROR(M16/J16,"-")) | S16: =IF(E16="","",IF(OR(NOT(ISNUMBER(N16)),N16<=(1-E16)),"erfüllt",IF(G16="Fehler","mit Fehler",IF(G16="Warnung","mit Warnung",""))))
A17: 10008 | B17: ALR | C17: Massnahmeref | I17: ALR | J17: =IF(E17="","",raw_data!C9) | M17: =IF(E17="","",raw_data!F9) | N17: =IF(E17="","",IFERROR(M17/J17,"-")) | S17: =IF(E17="","",IF(OR(NOT(ISNUMBER(N17)),N17<=(1-E17)),"erfüllt",IF(G17="Fehler","mit Fehler",IF(G17="Warnung","mit Warnung",""))))
A18: 10009 | B18: ALR | C18: Obj_Id_Entsorgung | I18: ALR | J18: =IF(E18="","",raw_data!C10) | M18: =IF(E18="","",raw_data!F10) | N18: =IF(E18="","",IFERROR(M18/J18,"-")) | S18: =IF(E18="","",IF(OR(NOT(ISNUMBER(N18)),N18<=(1-E18)),"erfüllt",IF(G18="Fehler","mit Fehler",IF(G18="Warnung","mit Warnung",""))))
A19: 10010 | B19: ALR | C19: Obj_Id_Entsorgung_Abwasserbauwerk | I19: ALR | J19: =IF(E19="","",raw_data!C11) | M19: =IF(E19="","",raw_data!F11) | N19: =IF(E19="","",IFERROR(M19/J19,"-")) | S19: =IF(E19="","",IF(OR(NOT(ISNUMBER(N19)),N19<=(1-E19)),"erfüllt",IF(G19="Fehler","mit Fehler",IF(G19="Warnung","mit Warnung",""))))
A20: 10011 | B20: ALR | C20: Obj_Id_Entsorgung_Einleitstelle | I20: ALR | J20: =IF(E20="","",raw_data!C12) | M20: =IF(E20="","",raw_data!F12) | N20: =IF(E20="","",IFERROR(M20/J20,"-")) | S20: =IF(E20="","",IF(OR(NOT(ISNUMBER(N20)),N20<=(1-E20)),"erfüllt",IF(G20="Fehler","mit Fehler",IF(G20="Warnung","mit Warnung",""))))
A21: 10012 | B21: ALR | C21: Obj_Id_Entsorgung_Versickerungsanlage | I21: ALR | J21: =IF(E21="","",raw_data!C13) | M21: =IF(E21="","",raw_data!F13) | N21: =IF(E21="","",IFERROR(M21/J21,"-")) | S21: =IF(E21="","",IF(OR(NOT(ISNUMBER(N21)),N21<=(1-E21)),"erfüllt",IF(G21="Fehler","mit Fehler",IF(G21="Warnung","mit Warnung",""))))
A22: 10013 | B22: ALR | C22: Obj_Id_Gebaeudegruppe_Entsorgung | I22: ALR | J22: =IF(E22="","",raw_data!C14) | M22: =IF(E22="","",raw_data!F14) | N22: =IF(E22="","",IFERROR(M22/J22,"-")) | S22: =IF(E22="","",IF(OR(NOT(ISNUMBER(N22)),N22<=(1-E22)),"erfüllt",IF(G22="Fehler","mit Fehler",IF(G22="Warnung","mit Warnung",""))))
A23: 10014 | B23: ALR | C23: OID | E23: 1 | G23: Fehler | I23: ALR | J23: =IF(E23="","",raw_data!C15) -> 0 | M23: =IF(E23="","",raw_data!F15) -> 0 | N23: =IF(E23="","",IFERROR(M23/J23,"-")) -> - | S23: =IF(E23="","",IF(OR(NOT(ISNUMBER(N23)),N23<=(1-E23)),"erfüllt",IF(G23="Fehler","mit Fehler",IF(G23="Warnung","mit Warnung","")))) -> erfüllt
A24: 10015a | B24: ALR | C24: Sanierungsbedarf | E24: 1 | G24: Warnung | I24: ALR | J24: =IF(E24="","",raw_data!C16) -> 0 | M24: =IF(E24="","",raw_data!F16) -> 0 | N24: =IF(E24="","",IFERROR(M24/J24,"-")) -> - | S24: =IF(E24="","",IF(OR(NOT(ISNUMBER(N24)),N24<=(1-E24)),"erfüllt",IF(G24="Fehler","mit Fehler",IF(G24="Warnung","mit Warnung","")))) -> erfüllt
A25: 10015b | B25: ALR | C25: Sanierungsbedarf | D25: not unbekannt | E25: 0.5 | G25: Warnung | I25: ALR | J25: =IF(E25="","",raw_data!C17) -> 0 | M25: =IF(E25="","",raw_data!F17) -> 0 | N25: =IF(E25="","",IFERROR(M25/J25,"-")) -> - | S25: =IF(E25="","",IF(OR(NOT(ISNUMBER(N25)),N25<=(1-E25)),"erfüllt",IF(G25="Fehler","mit Fehler",IF(G25="Warnung","mit Warnung","")))) -> erfüllt
A26: 10016 | B26: ALR | C26: Sanierungsdatum | I26: ALR | J26: =IF(E26="","",raw_data!C18) | M26: =IF(E26="","",raw_data!F18) | N26: =IF(E26="","",IFERROR(M26/J26,"-")) | S26: =IF(E26="","",IF(OR(NOT(ISNUMBER(N26)),N26<=(1-E26)),"erfüllt",IF(G26="Fehler","mit Fehler",IF(G26="Warnung","mit Warnung",""))))
A27: 10017 | B27: ALR | C27: Sanierungskonzept | I27: ALR | J27: =IF(E27="","",raw_data!C19) | M27: =IF(E27="","",raw_data!F19) | N27: =IF(E27="","",IFERROR(M27/J27,"-")) | S27: =IF(E27="","",IF(OR(NOT(ISNUMBER(N27)),N27<=(1-E27)),"erfüllt",IF(G27="Fehler","mit Fehler",IF(G27="Warnung","mit Warnung",""))))
A28: 11001 | B28: Knoten | C28: Ara_Nr | E28: 1 | F28: 1 | G28: Fehler | H28: Fehler | I28: Anlagenkataster | J28: =IF(E28="","",raw_data!C20) -> 0 | K28: =IF(E28="","",raw_data!D20) -> 0 | L28: =IF(F28="","",raw_data!E20) -> 0 | M28: =IF(E28="","",raw_data!F20) -> 0 | N28: =IF(E28="","",IFERROR(M28/J28,"-")) -> - | O28: =IF(E28="","",raw_data!G20) -> 0 | P28: =IF(E28="","",IFERROR(O28/K28,"-")) -> - | Q28: =IF(F28="","",raw_data!H20) -> 0 | R28: =IF(F28="","",IFERROR(Q28/L28,"-")) -> - | S28: =IF(E28="","",IF(OR(NOT(ISNUMBER(N28)),N28<=(1-E28)),"erfüllt",IF(G28="Fehler","mit Fehler",IF(G28="Warnung","mit Warnung","")))) -> erfüllt
A29: 11002a | B29: Knoten | C29: Status | E29: 1 | F29: 1 | G29: Fehler | H29: Fehler | I29: Anlagenkataster | J29: =IF(E29="","",raw_data!C21) -> 0 | K29: =IF(E29="","",raw_data!D21) -> 0 | L29: =IF(F29="","",raw_data!E21) -> 0 | M29: =IF(E29="","",raw_data!F21) -> 0 | N29: =IF(E29="","",IFERROR(M29/J29,"-")) -> - | O29: =IF(E29="","",raw_data!G21) -> 0 | P29: =IF(E29="","",IFERROR(O29/K29,"-")) -> - | Q29: =IF(F29="","",raw_data!H21) -> 0 | R29: =IF(F29="","",IFERROR(Q29/L29,"-")) -> - | S29: =IF(E29="","",IF(OR(NOT(ISNUMBER(N29)),N29<=(1-E29)),"erfüllt",IF(G29="Fehler","mit Fehler",IF(G29="Warnung","mit Warnung","")))) -> erfüllt
A30: 11002b | B30: Knoten | C30: Status | D30: not unbekannt | E30: 0.9 | F30: 0.5 | G30: Fehler | H30: Fehler | I30: Anlagenkataster | J30: =IF(E30="","",raw_data!C22) -> 0 | K30: =IF(E30="","",raw_data!D22) -> 0 | L30: =IF(F30="","",raw_data!E22) -> 0 | M30: =IF(E30="","",raw_data!F22) -> 0 | N30: =IF(E30="","",IFERROR(M30/J30,"-")) -> - | O30: =IF(E30="","",raw_data!G22) -> 0 | P30: =IF(E30="","",IFERROR(O30/K30,"-")) -> - | Q30: =IF(F30="","",raw_data!H22) -> 0 | R30: =IF(F30="","",IFERROR(Q30/L30,"-")) -> - | S30: =IF(E30="","",IF(OR(NOT(ISNUMBER(N30)),N30<=(1-E30)),"erfüllt",IF(G30="Fehler","mit Fehler",IF(G30="Warnung","mit Warnung","")))) -> erfüllt
A31: 11003 | B31: Knoten | C31: Baujahr | I31: Anlagenkataster | J31: =IF(E31="","",raw_data!C23) | K31: =IF(E31="","",raw_data!D23) | L31: =IF(F31="","",raw_data!E23) | M31: =IF(E31="","",raw_data!F23) | N31: =IF(E31="","",IFERROR(M31/J31,"-")) | O31: =IF(E31="","",raw_data!G23) | P31: =IF(E31="","",IFERROR(O31/K31,"-")) | Q31: =IF(F31="","",raw_data!H23) | R31: =IF(F31="","",IFERROR(Q31/L31,"-")) | S31: =IF(E31="","",IF(OR(NOT(ISNUMBER(N31)),N31<=(1-E31)),"erfüllt",IF(G31="Fehler","mit Fehler",IF(G31="Warnung","mit Warnung",""))))
A32: 11004a | B32: Knoten | C32: Baulicherzustand | E32: 1 | F32: 1 | G32: Fehler | H32: Fehler | I32: Z-S-U | J32: =IF(E32="","",raw_data!C24) -> 0 | K32: =IF(E32="","",raw_data!D24) -> 0 | L32: =IF(F32="","",raw_data!E24) -> 0 | M32: =IF(E32="","",raw_data!F24) -> 0 | N32: =IF(E32="","",IFERROR(M32/J32,"-")) -> - | O32: =IF(E32="","",raw_data!G24) -> 0 | P32: =IF(E32="","",IFERROR(O32/K32,"-")) -> - | Q32: =IF(F32="","",raw_data!H24) -> 0 | R32: =IF(F32="","",IFERROR(Q32/L32,"-")) -> - | S32: =IF(E32="","",IF(OR(NOT(ISNUMBER(N32)),N32<=(1-E32)),"erfüllt",IF(G32="Fehler","mit Fehler",IF(G32="Warnung","mit Warnung","")))) -> erfüllt
A33: 11004b | B33: Knoten | C33: Baulicherzustand | D33: not unbekannt | E33: 0.5 | G33: Fehler | I33: Z-S-U | J33: =IF(E33="","",raw_data!C25) -> 0 | K33: =IF(E33="","",raw_data!D25) -> 0 | L33: =IF(F33="","",raw_data!E25) | M33: =IF(E33="","",raw_data!F25) -> 0 | N33: =IF(E33="","",IFERROR(M33/J33,"-")) -> - | O33: =IF(E33="","",raw_data!G25) -> 0 | P33: =IF(E33="","",IFERROR(O33/K33,"-")) -> - | Q33: =IF(F33="","",raw_data!H25) | R33: =IF(F33="","",IFERROR(Q33/L33,"-")) | S33: =IF(E33="","",IF(OR(NOT(ISNUMBER(N33)),N33<=(1-E33)),"erfüllt",IF(G33="Fehler","mit Fehler",IF(G33="Warnung","mit Warnung","")))) -> erfüllt
A34: 11005 | B34: Knoten | C34: Bemerkung | I34: Anlagenkataster | J34: =IF(E34="","",raw_data!C26) | K34: =IF(E34="","",raw_data!D26) | L34: =IF(F34="","",raw_data!E26) | M34: =IF(E34="","",raw_data!F26) | N34: =IF(E34="","",IFERROR(M34/J34,"-")) | O34: =IF(E34="","",raw_data!G26) | P34: =IF(E34="","",IFERROR(O34/K34,"-")) | Q34: =IF(F34="","",raw_data!H26) | R34: =IF(F34="","",IFERROR(Q34/L34,"-")) | S34: =IF(E34="","",IF(OR(NOT(ISNUMBER(N34)),N34<=(1-E34)),"erfüllt",IF(G34="Fehler","mit Fehler",IF(G34="Warnung","mit Warnung",""))))
A35: 11006 | B35: Knoten | C35: Betreiberref | E35: 1 | G35: Warnung | I35: Anlagenkataster | J35: =IF(E35="","",raw_data!C27) -> 0 | K35: =IF(E35="","",raw_data!D27) -> 0 | L35: =IF(F35="","",raw_data!E27) | M35: =IF(E35="","",raw_data!F27) -> 0 | N35: =IF(E35="","",IFERROR(M35/J35,"-")) -> - | O35: =IF(E35="","",raw_data!G27) -> 0 | P35: =IF(E35="","",IFERROR(O35/K35,"-")) -> - | Q35: =IF(F35="","",raw_data!H27) | R35: =IF(F35="","",IFERROR(Q35/L35,"-")) | S35: =IF(E35="","",IF(OR(NOT(ISNUMBER(N35)),N35<=(1-E35)),"erfüllt",IF(G35="Fehler","mit Fehler",IF(G35="Warnung","mit Warnung","")))) -> erfüllt
A36: 11007a | B36: Knoten | C36: Bezeichnung | I36: Anlagenkataster | J36: =IF(E36="","",raw_data!C28) | K36: =IF(E36="","",raw_data!D28) | L36: =IF(F36="","",raw_data!E28) | M36: =IF(E36="","",raw_data!F28) | N36: =IF(E36="","",IFERROR(M36/J36,"-")) | O36: =IF(E36="","",raw_data!G28) | P36: =IF(E36="","",IFERROR(O36/K36,"-")) | Q36: =IF(F36="","",raw_data!H28) | R36: =IF(F36="","",IFERROR(Q36/L36,"-")) | S36: =IF(E36="","",IF(OR(NOT(ISNUMBER(N36)),N36<=(1-E36)),"erfüllt",IF(G36="Fehler","mit Fehler",IF(G36="Warnung","mit Warnung",""))))
A37: 11007b | B37: Knoten | C37: Bezeichnung | D37: eindeutig | E37: 1 | F37: 1 | G37: Fehler | H37: Fehler | I37: Anlagenkataster | J37: =IF(E37="","",raw_data!C29) -> 0 | K37: =IF(E37="","",raw_data!D29) -> 0 | L37: =IF(F37="","",raw_data!E29) -> 0 | M37: =IF(E37="","",raw_data!F29) -> 0 | N37: =IF(E37="","",IFERROR(M37/J37,"-")) -> - | O37: =IF(E37="","",raw_data!G29) -> 0 | P37: =IF(E37="","",IFERROR(O37/K37,"-")) -> - | Q37: =IF(F37="","",raw_data!H29) -> 0 | R37: =IF(F37="","",IFERROR(Q37/L37,"-")) -> - | S37: =IF(E37="","",IF(OR(NOT(ISNUMBER(N37)),N37<=(1-E37)),"erfüllt",IF(G37="Fehler","mit Fehler",IF(G37="Warnung","mit Warnung","")))) -> erfüllt
A38: 11008 | B38: Knoten | C38: Datenherrref | I38: Anlagenkataster | J38: =IF(E38="","",raw_data!C30) | K38: =IF(E38="","",raw_data!D30) | L38: =IF(F38="","",raw_data!E30) | M38: =IF(E38="","",raw_data!F30) | N38: =IF(E38="","",IFERROR(M38/J38,"-")) | O38: =IF(E38="","",raw_data!G30) | P38: =IF(E38="","",IFERROR(O38/K38,"-")) | Q38: =IF(F38="","",raw_data!H30) | R38: =IF(F38="","",IFERROR(Q38/L38,"-")) | S38: =IF(E38="","",IF(OR(NOT(ISNUMBER(N38)),N38<=(1-E38)),"erfüllt",IF(G38="Fehler","mit Fehler",IF(G38="Warnung","mit Warnung",""))))
A39: 11009 | B39: Knoten | C39: Datenlieferantref | I39: Anlagenkataster | J39: =IF(E39="","",raw_data!C31) | K39: =IF(E39="","",raw_data!D31) | L39: =IF(F39="","",raw_data!E31) | M39: =IF(E39="","",raw_data!F31) | N39: =IF(E39="","",IFERROR(M39/J39,"-")) | O39: =IF(E39="","",raw_data!G31) | P39: =IF(E39="","",IFERROR(O39/K39,"-")) | Q39: =IF(F39="","",raw_data!H31) | R39: =IF(F39="","",IFERROR(Q39/L39,"-")) | S39: =IF(E39="","",IF(OR(NOT(ISNUMBER(N39)),N39<=(1-E39)),"erfüllt",IF(G39="Fehler","mit Fehler",IF(G39="Warnung","mit Warnung",""))))
A40: 11010 | B40: Knoten | C40: Deckelkote | E40: 1 | G40: Warnung | I40: Entwässerungskonzept | J40: =IF(E40="","",raw_data!C32) -> 0 | K40: =IF(E40="","",raw_data!D32) -> 0 | L40: =IF(F40="","",raw_data!E32) | M40: =IF(E40="","",raw_data!F32) -> 0 | N40: =IF(E40="","",IFERROR(M40/J40,"-")) -> - | O40: =IF(E40="","",raw_data!G32) -> 0 | P40: =IF(E40="","",IFERROR(O40/K40,"-")) -> - | Q40: =IF(F40="","",raw_data!H32) | R40: =IF(F40="","",IFERROR(Q40/L40,"-")) | S40: =IF(E40="","",IF(OR(NOT(ISNUMBER(N40)),N40<=(1-E40)),"erfüllt",IF(G40="Fehler","mit Fehler",IF(G40="Warnung","mit Warnung","")))) -> erfüllt
A41: 11011 | B41: Knoten | C41: Detailgeometrie | I41: Anlagenkataster | J41: =IF(E41="","",raw_data!C33) | K41: =IF(E41="","",raw_data!D33) | L41: =IF(F41="","",raw_data!E33) | M41: =IF(E41="","",raw_data!F33) | N41: =IF(E41="","",IFERROR(M41/J41,"-")) | O41: =IF(E41="","",raw_data!G33) | P41: =IF(E41="","",IFERROR(O41/K41,"-")) | Q41: =IF(F41="","",raw_data!H33) | R41: =IF(F41="","",IFERROR(Q41/L41,"-")) | S41: =IF(E41="","",IF(OR(NOT(ISNUMBER(N41)),N41<=(1-E41)),"erfüllt",IF(G41="Fehler","mit Fehler",IF(G41="Warnung","mit Warnung",""))))
A42: 11012 | B42: Knoten | C42: Dimension1 | I42: Anlagenkataster | J42: =IF(E42="","",raw_data!C34) | K42: =IF(E42="","",raw_data!D34) | L42: =IF(F42="","",raw_data!E34) | M42: =IF(E42="","",raw_data!F34) | N42: =IF(E42="","",IFERROR(M42/J42,"-")) | O42: =IF(E42="","",raw_data!G34) | P42: =IF(E42="","",IFERROR(O42/K42,"-")) | Q42: =IF(F42="","",raw_data!H34) | R42: =IF(F42="","",IFERROR(Q42/L42,"-")) | S42: =IF(E42="","",IF(OR(NOT(ISNUMBER(N42)),N42<=(1-E42)),"erfüllt",IF(G42="Fehler","mit Fehler",IF(G42="Warnung","mit Warnung",""))))
...

Sheet raw_data
